Workbook

Sheet Instructions
A1: Vendor Selection Scorecard - Instructions
A3: Companion to the Raysho Vendor Selection Playbook. Use after the three conversations complete.
A5: HOW THIS SCORECARD WORKS
B7: Three conversations precede this scorecard. With the delivery manager (Conversation 1, 13 questions). With an independently located current client (Conversation 2, 14 questions). With the compliance officer (Conversation 3, 13 questions). See the 'Interview Questions' tab for the full question set.
B8: Up to four shortlisted vendors get one scorecard sheet each: Vendor A, Vendor B, Vendor C, Vendor D. For fewer vendors, leave the unused sheets empty. For more than four, duplicate one of the vendor sheets and rename.
B9: The 'Side-by-Side Summary' sheet reads from the four vendor sheets and produces the comparison view with a final shortlist verdict per vendor.
A11: SCORING DISCIPLINE
B13: Scores run 1 (poor) to 5 (strong). Half-scores (3.5, 4.5) are allowed. Every score needs a one-sentence justification in the adjacent cell, referencing a specific moment in one of the three conversations. A score without a justification is a gut call and will fail the review pass.
B14: The partner completes the scorecard alone, without the sales team present and without the shortlisted vendors present. Final review is the partner reading the justifications together with whoever else in the firm will carry the delivery relationship.
A16: CATEGORY WEIGHTS (FIXED)
B18: Delivery manager quality: 25% - Conversation 1 depth and specificity
B19: Client-reported delivery: 20% - Conversation 2 length and texture of answers
B20: Compliance and data handling: 20% - Conversation 3 document production during call
B21: Contract terms: 15% - willingness to accept the five clauses in playbook Section 7
B22: Price realism: 10% - price relative to scope without bundling tricks
B23: Cultural fit and communication style: 10% - aggregated across the three conversations
A25: SHORTLIST DECISION LOGIC
B27: Floor score: 3.50 weighted total. Below this, the vendor is not shortlisted regardless of individual strengths.
B28: Knockout criteria: Red flags 1, 3, 4, 5, and 12 trigger automatic exclusion regardless of weighted total. A vendor who scores well on every category but triggers a knockout flag is not shortlisted.
B29: Knockout red flags: (1) demo lead disappears after contract, (3) no named delivery manager before signature, (4) SOC 2 scope does not include delivery environment, (5) sub-processor list undisclosed, (12) no exit clause in contract.
A31: THE TWELVE RED FLAGS
B33: See the 'Red Flag Catalogue' tab for the full reference. Each red flag has a Yes / No checkbox on the vendor sheet. Yes on any of the five knockout flags triggers automatic exclusion.
A35: VERDICT OUTPUT
B37: Three possible outcomes per vendor:
B38: SHORTLIST - weighted total is 3.50 or above, and no knockout red flag triggered. The vendor earned the work.
B39: BELOW FLOOR - weighted total is below 3.50. Not shortlisted on score alone.
B40: KNOCKOUT - one or more knockout red flags triggered. Not shortlisted regardless of score.
A42: WHAT TO DO AFTER SCORING
B44: Shortlist only vendors that scored SHORTLIST on the verdict output. Negotiate the five contract clauses (see playbook Section 7) with the shortlisted vendors before final selection. A vendor who refuses all five clauses at contract has given the partner a fourteenth signal, and the decision can unwind.
B45: Archive the completed scorecard with the engagement file. This is the audit trail for why the vendor was chosen, and the reference point if the partner evaluates a replacement vendor later.
A47: VERSION
B49: v1.0 - 2026-04-21. Produced by Raysho. Companion to S-F-006 Vendor Selection Playbook. Redistribution permitted with attribution.

Sheet Side-by-Side Summary
A1: Side-by-Side Summary
A3: Read-only view. Scores, red flags, and verdicts pull from the four vendor sheets.
B5: Metric | C5: Vendor A | D5: Vendor B | E5: Vendor C | F5: Vendor D
B6: Vendor name | C6: ='Vendor A'!C4 -> 0 | D6: ='Vendor B'!C4 -> 0 | E6: ='Vendor C'!C4 -> 0 | F6: ='Vendor D'!C4 -> 0
B7: Weighted total (out of 5.00) | C7: ='Vendor A'!F42 -> 0 | D7: ='Vendor B'!F42 -> 0 | E7: ='Vendor C'!F42 -> 0 | F7: ='Vendor D'!F42 -> 0
B8: Knockout triggered? | C8: ='Vendor A'!C31 -> No | D8: ='Vendor B'!C31 -> No | E8: ='Vendor C'!C31 -> No | F8: ='Vendor D'!C31 -> No
B9: FINAL VERDICT | C9: ='Vendor A'!B45 -> Awaiting scores | D9: ='Vendor B'!B45 -> Awaiting scores | E9: ='Vendor C'!B45 -> Awaiting scores | F9: ='Vendor D'!B45 -> Awaiting scores
B12: Decision rule: Only vendors showing SHORTLIST on the verdict row are taken to contract negotiation. Verify the five contract clauses (SLA enforcement, data ownership, exit clause, liability cap, SOC 2 maintenance) with each shortlisted vendor before final selection. A vendor refusing all five clauses at contract unwinds the decision.

Sheet Vendor A
A1: Vendor Scorecard - Vendor A
A3: Vendor identity and engagement scope
B4: Vendor name
B5: HQ country
B6: Delivery country (where staff physically sit)
B7: Proposed engagement size (FTE or monthly fee)
B8: Date of Conversation 1 (delivery manager)
B9: Name of delivery manager interviewed
B10: Date of Conversation 2 (independent client)
B11: Name of client interviewed (how found)
B12: Date of Conversation 3 (compliance officer)
B13: Name of compliance officer interviewed
B14: SOC 2 report reviewed under NDA? (Y/N + date)
A16: Red flag knockout check (12 flags; flags 1, 3, 4, 5, 12 are knockout triggers)
B17: Red flag | C17: Trigger? | D17: Evidence from conversations | E17: Knockout?
B18: #1. Demo lead disappears after contract | C18: No | E18: KNOCKOUT
B19: #2. Reference clients all more than 2 years old | C19: No
B20: #3. No named delivery manager before signature | C20: No | E20: KNOCKOUT
B21: #4. SOC 2 scope does not include delivery environment | C21: No | E21: KNOCKOUT
B22: #5. Sub-processor list undisclosed | C22: No | E22: KNOCKOUT
B23: #6. No client termination history discussed | C23: No
B24: #7. Vague answers on data export controls | C24: No
B25: #8. Pricing bundled to prevent comparison | C25: No
B26: #9. Exclusivity or minimum volume in first year | C26: No
B27: #10. No written escalation process | C27: No
B28: #11. Reference client is on vendor advisory board | C28: No
B29: #12. No exit clause in contract | C29: No | E29: KNOCKOUT
B31: Any knockout red flag triggered? | C31: =IF(OR(C18="Yes",C20="Yes",C21="Yes",C22="Yes",C29="Yes"),"YES - KNOCKOUT","No") -> No
A33: Weighted scoring (1 = poor, 5 = strong; half-scores allowed)
B34: Category | C34: Score (1-5) | D34: Justification (one sentence, conversation reference) | E34: Weight | F34: Weighted
B35: Delivery manager quality | D35: [Conversation 1, question-by-question depth and specificity] | E35: 0.25 | F35: =IF(ISNUMBER(C35),C35*E35,0) -> 0
B36: Client-reported delivery | D36: [Conversation 2, length and texture of answers, question 14 response] | E36: 0.2 | F36: =IF(ISNUMBER(C36),C36*E36,0) -> 0
B37: Compliance and data handling | D37: [Conversation 3, document production during call, scope of SOC 2] | E37: 0.2 | F37: =IF(ISNUMBER(C37),C37*E37,0) -> 0
B38: Contract terms | D38: [Willingness to accept the five clauses in playbook Section 7] | E38: 0.15 | F38: =IF(ISNUMBER(C38),C38*E38,0) -> 0
B39: Price realism | D39: [Price relative to scope without bundling tricks] | E39: 0.1 | F39: =IF(ISNUMBER(C39),C39*E39,0) -> 0
B40: Cultural fit and communication style | D40: [Aggregated across the three conversations] | E40: 0.1 | F40: =IF(ISNUMBER(C40),C40*E40,0) -> 0
B41: Weight check (should total 100%) | E41: =SUM(E35:E40) -> 1
B42: WEIGHTED TOTAL | C42: Sum of weighted scores (maximum 5.00; floor for shortlist is 3.50) | F42: =SUM(F35:F40) -> 0
B44: FINAL VERDICT
B45: =IF(C31="YES - KNOCKOUT","KNOCKOUT - not shortlisted",IF(F42>=3.5,"SHORTLIST - proceed to contract negotiation",IF(F42>0,"BELOW FLOOR - not shortlisted","Awaiting scores"))) -> Awaiting scores
...

Sheet Vendor B
A1: Vendor Scorecard - Vendor B
A3: Vendor identity and engagement scope
B4: Vendor name
B5: HQ country
B6: Delivery country (where staff physically sit)
B7: Proposed engagement size (FTE or monthly fee)
B8: Date of Conversation 1 (delivery manager)
B9: Name of delivery manager interviewed
B10: Date of Conversation 2 (independent client)
B11: Name of client interviewed (how found)
B12: Date of Conversation 3 (compliance officer)
B13: Name of compliance officer interviewed
B14: SOC 2 report reviewed under NDA? (Y/N + date)
A16: Red flag knockout check (12 flags; flags 1, 3, 4, 5, 12 are knockout triggers)
B17: Red flag | C17: Trigger? | D17: Evidence from conversations | E17: Knockout?
B18: #1. Demo lead disappears after contract | C18: No | E18: KNOCKOUT
B19: #2. Reference clients all more than 2 years old | C19: No
B20: #3. No named delivery manager before signature | C20: No | E20: KNOCKOUT
B21: #4. SOC 2 scope does not include delivery environment | C21: No | E21: KNOCKOUT
B22: #5. Sub-processor list undisclosed | C22: No | E22: KNOCKOUT
B23: #6. No client termination history discussed | C23: No
B24: #7. Vague answers on data export controls | C24: No
B25: #8. Pricing bundled to prevent comparison | C25: No
B26: #9. Exclusivity or minimum volume in first year | C26: No
B27: #10. No written escalation process | C27: No
B28: #11. Reference client is on vendor advisory board | C28: No
B29: #12. No exit clause in contract | C29: No | E29: KNOCKOUT
B31: Any knockout red flag triggered? | C31: =IF(OR(C18="Yes",C20="Yes",C21="Yes",C22="Yes",C29="Yes"),"YES - KNOCKOUT","No") -> No
A33: Weighted scoring (1 = poor, 5 = strong; half-scores allowed)
B34: Category | C34: Score (1-5) | D34: Justification (one sentence, conversation reference) | E34: Weight | F34: Weighted
B35: Delivery manager quality | D35: [Conversation 1, question-by-question depth and specificity] | E35: 0.25 | F35: =IF(ISNUMBER(C35),C35*E35,0) -> 0
B36: Client-reported delivery | D36: [Conversation 2, length and texture of answers, question 14 response] | E36: 0.2 | F36: =IF(ISNUMBER(C36),C36*E36,0) -> 0
B37: Compliance and data handling | D37: [Conversation 3, document production during call, scope of SOC 2] | E37: 0.2 | F37: =IF(ISNUMBER(C37),C37*E37,0) -> 0
B38: Contract terms | D38: [Willingness to accept the five clauses in playbook Section 7] | E38: 0.15 | F38: =IF(ISNUMBER(C38),C38*E38,0) -> 0
B39: Price realism | D39: [Price relative to scope without bundling tricks] | E39: 0.1 | F39: =IF(ISNUMBER(C39),C39*E39,0) -> 0
B40: Cultural fit and communication style | D40: [Aggregated across the three conversations] | E40: 0.1 | F40: =IF(ISNUMBER(C40),C40*E40,0) -> 0
B41: Weight check (should total 100%) | E41: =SUM(E35:E40) -> 1
B42: WEIGHTED TOTAL | C42: Sum of weighted scores (maximum 5.00; floor for shortlist is 3.50) | F42: =SUM(F35:F40) -> 0
B44: FINAL VERDICT
B45: =IF(C31="YES - KNOCKOUT","KNOCKOUT - not shortlisted",IF(F42>=3.5,"SHORTLIST - proceed to contract negotiation",IF(F42>0,"BELOW FLOOR - not shortlisted","Awaiting scores"))) -> Awaiting scores
...

Sheet Vendor C
A1: Vendor Scorecard - Vendor C
A3: Vendor identity and engagement scope
B4: Vendor name
B5: HQ country
B6: Delivery country (where staff physically sit)
B7: Proposed engagement size (FTE or monthly fee)
B8: Date of Conversation 1 (delivery manager)
B9: Name of delivery manager interviewed
B10: Date of Conversation 2 (independent client)
B11: Name of client interviewed (how found)
B12: Date of Conversation 3 (compliance officer)
B13: Name of compliance officer interviewed
B14: SOC 2 report reviewed under NDA? (Y/N + date)
A16: Red flag knockout check (12 flags; flags 1, 3, 4, 5, 12 are knockout triggers)
B17: Red flag | C17: Trigger? | D17: Evidence from conversations | E17: Knockout?
B18: #1. Demo lead disappears after contract | C18: No | E18: KNOCKOUT
B19: #2. Reference clients all more than 2 years old | C19: No
B20: #3. No named delivery manager before signature | C20: No | E20: KNOCKOUT
B21: #4. SOC 2 scope does not include delivery environment | C21: No | E21: KNOCKOUT
B22: #5. Sub-processor list undisclosed | C22: No | E22: KNOCKOUT
B23: #6. No client termination history discussed | C23: No
B24: #7. Vague answers on data export controls | C24: No
B25: #8. Pricing bundled to prevent comparison | C25: No
B26: #9. Exclusivity or minimum volume in first year | C26: No
B27: #10. No written escalation process | C27: No
B28: #11. Reference client is on vendor advisory board | C28: No
B29: #12. No exit clause in contract | C29: No | E29: KNOCKOUT
B31: Any knockout red flag triggered? | C31: =IF(OR(C18="Yes",C20="Yes",C21="Yes",C22="Yes",C29="Yes"),"YES - KNOCKOUT","No") -> No
A33: Weighted scoring (1 = poor, 5 = strong; half-scores allowed)
B34: Category | C34: Score (1-5) | D34: Justification (one sentence, conversation reference) | E34: Weight | F34: Weighted
B35: Delivery manager quality | D35: [Conversation 1, question-by-question depth and specificity] | E35: 0.25 | F35: =IF(ISNUMBER(C35),C35*E35,0) -> 0
B36: Client-reported delivery | D36: [Conversation 2, length and texture of answers, question 14 response] | E36: 0.2 | F36: =IF(ISNUMBER(C36),C36*E36,0) -> 0
B37: Compliance and data handling | D37: [Conversation 3, document production during call, scope of SOC 2] | E37: 0.2 | F37: =IF(ISNUMBER(C37),C37*E37,0) -> 0
B38: Contract terms | D38: [Willingness to accept the five clauses in playbook Section 7] | E38: 0.15 | F38: =IF(ISNUMBER(C38),C38*E38,0) -> 0
B39: Price realism | D39: [Price relative to scope without bundling tricks] | E39: 0.1 | F39: =IF(ISNUMBER(C39),C39*E39,0) -> 0
B40: Cultural fit and communication style | D40: [Aggregated across the three conversations] | E40: 0.1 | F40: =IF(ISNUMBER(C40),C40*E40,0) -> 0
B41: Weight check (should total 100%) | E41: =SUM(E35:E40) -> 1
B42: WEIGHTED TOTAL | C42: Sum of weighted scores (maximum 5.00; floor for shortlist is 3.50) | F42: =SUM(F35:F40) -> 0
B44: FINAL VERDICT
B45: =IF(C31="YES - KNOCKOUT","KNOCKOUT - not shortlisted",IF(F42>=3.5,"SHORTLIST - proceed to contract negotiation",IF(F42>0,"BELOW FLOOR - not shortlisted","Awaiting scores"))) -> Awaiting scores
...

Sheet Vendor D
A1: Vendor Scorecard - Vendor D
A3: Vendor identity and engagement scope
B4: Vendor name
B5: HQ country
B6: Delivery country (where staff physically sit)
B7: Proposed engagement size (FTE or monthly fee)
B8: Date of Conversation 1 (delivery manager)
B9: Name of delivery manager interviewed
B10: Date of Conversation 2 (independent client)
B11: Name of client interviewed (how found)
B12: Date of Conversation 3 (compliance officer)
B13: Name of compliance officer interviewed
B14: SOC 2 report reviewed under NDA? (Y/N + date)
A16: Red flag knockout check (12 flags; flags 1, 3, 4, 5, 12 are knockout triggers)
B17: Red flag | C17: Trigger? | D17: Evidence from conversations | E17: Knockout?
B18: #1. Demo lead disappears after contract | C18: No | E18: KNOCKOUT
B19: #2. Reference clients all more than 2 years old | C19: No
B20: #3. No named delivery manager before signature | C20: No | E20: KNOCKOUT
B21: #4. SOC 2 scope does not include delivery environment | C21: No | E21: KNOCKOUT
B22: #5. Sub-processor list undisclosed | C22: No | E22: KNOCKOUT
B23: #6. No client termination history discussed | C23: No
B24: #7. Vague answers on data export controls | C24: No
B25: #8. Pricing bundled to prevent comparison | C25: No
B26: #9. Exclusivity or minimum volume in first year | C26: No
B27: #10. No written escalation process | C27: No
B28: #11. Reference client is on vendor advisory board | C28: No
B29: #12. No exit clause in contract | C29: No | E29: KNOCKOUT
B31: Any knockout red flag triggered? | C31: =IF(OR(C18="Yes",C20="Yes",C21="Yes",C22="Yes",C29="Yes"),"YES - KNOCKOUT","No") -> No
A33: Weighted scoring (1 = poor, 5 = strong; half-scores allowed)
B34: Category | C34: Score (1-5) | D34: Justification (one sentence, conversation reference) | E34: Weight | F34: Weighted
B35: Delivery manager quality | D35: [Conversation 1, question-by-question depth and specificity] | E35: 0.25 | F35: =IF(ISNUMBER(C35),C35*E35,0) -> 0
B36: Client-reported delivery | D36: [Conversation 2, length and texture of answers, question 14 response] | E36: 0.2 | F36: =IF(ISNUMBER(C36),C36*E36,0) -> 0
B37: Compliance and data handling | D37: [Conversation 3, document production during call, scope of SOC 2] | E37: 0.2 | F37: =IF(ISNUMBER(C37),C37*E37,0) -> 0
B38: Contract terms | D38: [Willingness to accept the five clauses in playbook Section 7] | E38: 0.15 | F38: =IF(ISNUMBER(C38),C38*E38,0) -> 0
B39: Price realism | D39: [Price relative to scope without bundling tricks] | E39: 0.1 | F39: =IF(ISNUMBER(C39),C39*E39,0) -> 0
B40: Cultural fit and communication style | D40: [Aggregated across the three conversations] | E40: 0.1 | F40: =IF(ISNUMBER(C40),C40*E40,0) -> 0
B41: Weight check (should total 100%) | E41: =SUM(E35:E40) -> 1
B42: WEIGHTED TOTAL | C42: Sum of weighted scores (maximum 5.00; floor for shortlist is 3.50) | F42: =SUM(F35:F40) -> 0
B44: FINAL VERDICT
B45: =IF(C31="YES - KNOCKOUT","KNOCKOUT - not shortlisted",IF(F42>=3.5,"SHORTLIST - proceed to contract negotiation",IF(F42>0,"BELOW FLOOR - not shortlisted","Awaiting scores"))) -> Awaiting scores
...

Sheet Red Flag Catalogue
A1: Red Flag Catalogue - Reference
B4: # | C4: Red flag | D4: Failure mode predicted | E4: Type
B5: 1 | C5: Demo lead disappears after contract | D5: The vendor's best person is a sales asset, not a delivery asset. | E5: KNOCKOUT
B6: 2 | C6: Reference clients all more than 2 years old | D6: Vendor is losing new clients faster than keeping old ones; partner is being asked to become the new logo. | E6: Flag
B7: 3 | C7: No named delivery manager before signature | D7: Partner cannot verify the actual delivery resource until too late to change the decision. | E7: KNOCKOUT
B8: 4 | C8: SOC 2 scope does not include delivery environment | D8: The compliance claim is technically true and operationally meaningless. | E8: KNOCKOUT
B9: 5 | C9: Sub-processor list undisclosed | D9: Partner cannot assess downstream risk or do their own due diligence on any third party. | E9: KNOCKOUT
B10: 6 | C10: No client termination history discussed | D10: Vendor is concealing the pattern or is not learning from it. Either case predicts repetition. | E10: Flag
B11: 7 | C11: Vague answers on data export controls | D11: The controls probably do not exist at the claimed level. | E11: Flag
B12: 8 | C12: Pricing bundled to prevent comparison | D12: Partner cannot see where value lives or renegotiate specific line items later. | E12: Flag
B13: 9 | C13: Exclusivity or minimum volume in first year | D13: Partner is locked in before delivery quality is proven. | E13: Flag
B14: 10 | C14: No written escalation process | D14: Escalation becomes an interpersonal negotiation every time, not a procedural one. | E14: Flag
B15: 11 | C15: Reference client is on vendor advisory board | D15: Reference is a fiduciary of the vendor and cannot speak freely. | E15: Flag
B16: 12 | C16: No exit clause in contract | D16: Leaving the vendor becomes an ordeal the partner does not want to pay for; staying becomes the default regardless of performance. | E16: KNOCKOUT

Sheet Interview Questions
A1: The Three Conversations - 40 Interview Questions
A4: CONVERSATION 1 - Delivery manager (13 questions)
B5: Experience and fit
B6: 1 | C6: Which three accounts on your current book look most like our firm in size, client mix, and complexity? Walk me through one of them from onboarding to current state.
B7: 2 | C7: On that account, what was the hardest thing about the first ninety days, and what did you do about it?
B8: 3 | C8: Which part of the onboarding tends to go slower than clients expect, and why?
B9: Process and discipline
B10: 4 | C10: Describe your month-end close calendar for a typical client. Who owns which day, and what is the escalation if a day slips?
B11: 5 | C11: Walk me through how you handle a bank feed that breaks on the third day of close week.
B12: 6 | C12: What does your quality-control process look like? Who reviews whose work, and what percentage of closes get reviewed at what depth?
B13: 7 | C13: How do you document exceptions and one-off client decisions so the next reviewer sees them?
B14: Communication and governance
B15: 8 | C15: What is your standing cadence with a client partner? What is the agenda?
B16: 9 | C16: When a close is going to miss the target date, when and how do you communicate that, and to whom?
B17: 10 | C17: What is your approach to client data requests that arrive outside the monthly cycle? Describe the last ad-hoc request you handled and the turnaround.
B18: Judgement
B19: 11 | C19: Describe a close where the numbers told you one story and the client's commentary told you another. How did you resolve it?
B20: 12 | C20: What is a mistake your team has made in the last six months that you would want me to know about, and what did you put in place after it?
B21: 13 | C21: If the engagement was offered to you today, what would you want in the statement of work that is not in the RFP?
A23: CONVERSATION 2 - Independently located current client (14 questions)
B24: How to find this client (not from the vendor's reference list)
B25: LinkedIn search for 'outsourced [vendor name]' or '[vendor name] accounting'. Industry-association member directories in the partner's space. Direct approach through a professional body (state CPA society, ICAEW, CPA Canada, CA ANZ) asking 'who in your network uses [vendor name] and would be willing to speak to someone evaluating them'. Cold approaches work when the partner states purpose, requests fifteen minutes, and offers reciprocity if possible.
B26: Onboarding experience
B27: 1 | C27: How long did the onboarding actually take against the vendor's quoted timeline?
B28: 2 | C28: What was the single biggest gap between what you expected and what showed up in the first ninety days?
B29: 3 | C29: What would you do differently about the onboarding now, if you were starting again?
B30: Ongoing delivery
B31: 4 | C31: How accurate is the monthly close against the committed calendar? Over the last year, how many closes slipped, and by how much?
B32: 5 | C32: How much of your time, as the client partner, actually goes into the relationship each month?
B33: 6 | C33: When the work is wrong, how is it wrong? What are the typical errors you find?
B34: 7 | C34: Who on the vendor side gets your call when something is urgent? How quickly do they respond?
B35: Communication and escalation
B36: 8 | C36: Has a delivery manager changed on you? How was that handled?
B37: 9 | C37: Describe the worst incident in the relationship so far and how it was resolved.
B38: 10 | C38: Do you feel the vendor hides problems from you, or surfaces them?
B39: Value and pricing
B40: 11 | C40: How has pricing moved since you signed? What triggers repricing conversations?
B41: 12 | C41: What is the vendor billing you for that you do not think you are getting value from?
B42: Counterfactual
B43: 13 | C43: If you were shopping for a vendor today, would you pick this one again? Why or why not?
...
